Workbook

Sheet Full survey table
C1: Q1: Name + Job title | F1: Q2: Knowledge of GMA status? | I1: Q3: Population growth? | R1: Q4: Selling water to other towns? | V1: Q5: Recent expansion? | AE1: Q6: How do you raise funds for water infrastructure expansion? | AO1: Q7: Calculation knowledge? | AU1: Q8: GIS tool use? | BA1: Q9: Anything you want to add? | BD1: EDB_1: Budget & Debt External data
A2: County | B2: Town | C2: Useful Survey Participation <DI> (Y/N) | D2: Cleaned | E2: Notes / Transcription [Raw] | F2: Knowledge of GMA Status <IR> (Y/N) | G2: Notes / Transcription [Raw] | H2: Fact Check [Post-Survey]: Actual County GMA status | I2: Did Population grow in the last 10 years? <IR> (Y/N) | J2: Notes / Transcription [Raw] | K2: Fact Check Comparison [Post-Survey] | L2: Pre-growth population <FI> [2014, per OFM] | M2: 2024 Population <FI> | N2: 2014 - 2024 Population Growth % <CM> | O2: 2024 Population Greater than median? <CM> (Y/N) | P2: Pop. growth equal to or above White Salmon's? [10.15] <CM> (Y/N) | Q2: Population growth above median? [2.89] <CM> (Y/N) | R2: Selling water to other towns? <IR> (Y/N) | S2: Notes / Transcription [Raw] | T2: Selling to individual customers? <IR> (Y/N) | U2: edge case? Is this qualitatively interesting? <DI> (Y/N) | V2: Water Infrastructure expansion within the last 10 years? <IR> (Y/N) | W2: Notes / Transcription [Raw] | X2: A bit more than 10 years ago? <IR> (Y/N) | Y2: Not Including Connections? <IR> (Y/N) | Z2: Connections expansion? <IR> (Y/N) | AA2: Aquifer Storage expansion? <IR> (Y/N) | AB2: Water Sources expansion? <IR> (Y/N) | AC2: Water Treatment expansion? <IR> (Y/N) | AD2: Sewage expansion [not connections]? <IR> (Y/N) | AE2: Knowledge of funding methodology? <IR> (Y/N) | AF2: Notes / Transcription [Raw] | AG2: Tax rates [explicit] <IR> (Y/N) | AH2: Development charge [unsure] <IR> (Y/N) | AI2: Connection fee <IR> (Y/N) | AJ2: SDC [explicit] <IR> (Y/N) | AK2: CFC [explicit] <IR> (Y/N) | AL2: Impact fee [explicit] <IR> (Y/N) | AM2: Grants? <IR> (Y/N) | AN2: Other/ edge case [explicit] <DI> (Y/N) | AO2: Knowledge of calculation specifics involved in funding methodology? <IR> (Y/N) | AP2: Notes / Transcription [Raw] | AQ2: Meter size [primarily] <IR> (Y/N) | AR2: ERUs [primarily] <IR> (Y/N) | AS2: Grandfathered / inflation adjusted <IR> (Y/N) | AT2: Overall cost analysis [primarily] <IR> (Y/N) | AU2: GIS tool use? <IR> (Y/N) | AV2: Notes / Transcription [Raw] | AW2: For meter location? <IR> (Y/N) | AX2: For asset valuation & fee calculations? <IR> (Y/N) | AY2: Separate tool for asset valuation? <IR> (Y/N) | AZ2: Name of GIS tool, name of separate asset valuation tool | BA2: Notes / Transcription [Raw] | BB2: Important details from secondary interviewee [usually info on who to actually interview instead of them] | BC2: Additional comments/ notes from interviewee [me] | BD2: Total Budget ($) FY2024 actual total expenditures, all funds <FI> | BE2: Budget – Source & Year | BF2: Capital & Bonded Debt ($) [CALCULATED — debt-type filter, excl. pension/OPEB] <FI> | BG2: Capital & Bonded Debt per capita <CM> | BH2: Official Total Liabilities ($) [DIRECT — official Schedule 09 filed total, all liabilities] <FI> | BI2: Filtered Debt ($) [CALCULATED — keyword filter, including only charges related to water infrastructure ] <FI> | BJ2: Debt – Source, Water/Sewer Portion & Context | BK2: Full Debt per capita <CM> | BL2: Debt to Population regression residuals <CM>
A3: Adams | B3: Othello | C3: Y | E3: public works director for Othello | F3: N | H3: Partially Planning | I3: Y | J3: 9,000 now, were closer to 7,500 | K3: Survey had 7,500 / 9,000 (close to OFM 7,780 / 9,210) | L3: 7695 | M3: 9145 | N3: =((M3 - L3) / L3) * 100 -> 18.843405 | O3: {=IF(M3 > MEDIAN(_xlfn._xlws.FILTER(M:M, C:C="Y")),"Y","N")} -> Y | P3: =IF(N3 >= 10.15, "Y", "N") -> Y | Q3: {=IF(N3 > MEDIAN(_xlfn._xlws.FILTER(N:N, C:C="Y")), "Y", "N")} -> Y | R3: N | T3: N | U3: N | V3: Y | W3: developments are responsible for adding infrastructure not us, but we have added 2 new wells. | X3: N | Y3: =IF(C3="N", "", IF(AND(C3="Y", OR(AA3="Y", AB3="Y", AC3="Y", AD3="Y")), "Y", "N")) -> Y | Z3: Y | AA3: N | AB3: Y | AC3: N | AD3: N | AE3: Y | AF3: These were calculated prior to me, not sure how this was developed. Part of our development fees, (not sure what formal name is for these) | AG3: N | AH3: Y | AI3: N | AJ3: N | AK3: N | AL3: N | AM3: N | AN3: N | AO3: Y | AP3: fees for developers are 2% for whatever the infrastructure cost is. | AQ3: N | AR3: N | AS3: N | AT3: Y | AU3: N | AW3: N/A | AX3: N/A | AY3: N/A | AZ3: N/A | BC3: third survey | BD3: 22250763 | BE3: FY2024 actual total expenditures, all funds (operating + capital/debt service). Source: WA State Auditor FIT, schedule1AggregationsByGovt (sections 30+35), MCAG 0188. portal.sao.wa.gov/FIT. | BF3: 4238690 | BG3: =BF3 /M3 -> 463.49809 | BH3: 7816828 | BI3: 2427269 | BJ3: FY2024 Schedule 09 via SAO FIT API (Snapshots/Schedule9s, MCAG 0188). Col E 'Outstanding Debt' = CALCULATED: total LT principal EXCLUDING pension/OPEB/compensated absences (excluded by debt-type code — reliable). Col F 'Official Total Liabilities' = DIRECT: grand total of the Schedule 09 as filed with SAO (all liabilities incl. pension/OPEB; no pattern matching). WATER/SEWER portion ~$2,427,269 [REGEX/KEYWORD — IMPRECISE: matched on debt-description text only (no fund tag in FIT); approximate]. | BK3: =BH3 / M3 -> 854.76523 | BL3: ='log(debt) vs log(pop.) normaliz'!H3 -> -0.35664911
A4: Adams | B4: Ritzville | C4: N | H4: Partially Planning | L4: 1680 | M4: 1790 | N4: =((M4 - L4) / L4) * 100 -> 6.547619 | O4: {=IF(M4 > MEDIAN(_xlfn._xlws.FILTER(M:M, C:C="Y")),"Y","N")} -> N | P4: =IF(N4 >= 10.15, "Y", "N") -> N | Q4: {=IF(N4 > MEDIAN(_xlfn._xlws.FILTER(N:N, C:C="Y")), "Y", "N")} -> Y | Y4: =IF(C4="N", "", IF(AND(C4="Y", OR(AA4="Y", AB4="Y", AC4="Y", AD4="Y")), "Y", "N")) | BD4: 7938329 | BE4: FY2024 actual total expenditures, all funds (operating + capital/debt service). Source: WA State Auditor FIT, schedule1AggregationsByGovt (sections 30+35), MCAG 0191. portal.sao.wa.gov/FIT. | BF4: 7316901 | BG4: =BF4 /M4 -> 4087.6542 | BH4: 7424624 | BI4: 2098924 | BJ4: FY2024 Schedule 09 via SAO FIT API (Snapshots/Schedule9s, MCAG 0191). Col E 'Outstanding Debt' = CALCULATED: total LT principal EXCLUDING pension/OPEB/compensated absences (excluded by debt-type code — reliable). Col F 'Official Total Liabilities' = DIRECT: grand total of the Schedule 09 as filed with SAO (all liabilities incl. pension/OPEB; no pattern matching). WATER/SEWER portion ~$2,098,924 [REGEX/KEYWORD — IMPRECISE: matched on debt-description text only (no fund tag in FIT); approximate]. | BK4: =BH4 / M4 -> 4147.8346 | BL4: ='log(debt) vs log(pop.) normaliz'!H4 -> 1.3250712
A5: Asotin | B5: Clarkston [Asotin PUD] | C5: Y | E5: Bob Sischo, Director of finance and administration for the public utilities district of Asotin. Handles water utilities for all of the towns & communities in Asotin. | F5: N | H5: Partially Planning | I5: N | J5: Some influx during COVID, nothing significant though in terms of population growth. Large geographic county, population base is well centered in Asotin (city) and Clarkston. | L5: 7225 | M5: 7240 | N5: =((M5 - L5) / L5) * 100 -> 0.20761246 | O5: {=IF(M5 > MEDIAN(_xlfn._xlws.FILTER(M:M, C:C="Y")),"Y","N")} -> Y | P5: =IF(N5 >= 10.15, "Y", "N") -> N | Q5: {=IF(N5 > MEDIAN(_xlfn._xlws.FILTER(N:N, C:C="Y")), "Y", "N")} -> N | R5: Y | S5: Based upon their consumption beyond their alloted amount. Asotin has a water system that gives alloted amounts of water to residents, excess is handled by the utilities district. | T5: Y | U5: Y | V5: Y | W5: No, a couple of subdivisions (multiple connections) but nothing major | X5: N | Y5: =IF(C5="N", "", IF(AND(C5="Y", OR(AA5="Y", AB5="Y", AC5="Y", AD5="Y")), "Y", "N")) -> N | Z5: Y | AA5: N | AB5: N | AC5: N | AD5: N | AE5: Y | AF5: Development pays for development approach. If someone require a subdivions, the developer is required to devlop it for us, then they hand it to us. We don’t put up funds or anything like that. SDCs are wrapped into the connection fees, but we arent really building out, so we never have capacity issues, only at 50%. | AG5: N | AH5: N | AI5: Y | AJ5: Y | AK5: N | AL5: N | AM5: N | AN5: N | AO5: Y | AP5: Connection fees are based more consumption, and cost of the connection. What is it costing us in terms of maintence? We arent dealing with capacity or urban sprawl, so our fees can be almost entirely around our cost base and maintenance projections. | AQ5: N | AR5: N | AS5: N | AT5: Y | AU5: Y | AV5: Yes, kind of for asset valuation. Mostly to maintain our system, pressure zones. | AW5: Y | AX5: Y | AY5: N | BC5: Good survey with the Public utilities district director Bob Sischo (people who actually handle water utiliteis in Asotin, not the public works director in this case.) | BD5: 18032979 | BE5: FY2024 actual total expenditures, all funds (operating + capital/debt service). Source: WA State Auditor FIT, schedule1AggregationsByGovt (sections 30+35), MCAG 0197. portal.sao.wa.gov/FIT. | BF5: 558518 | BG5: =BF5 /M5 -> 77.14337 | BH5: 5933169 | BI5: 0 | BJ5: FY2024 Schedule 09 via SAO FIT API (Snapshots/Schedule9s, MCAG 0197). Col E 'Outstanding Debt' = CALCULATED: total LT principal EXCLUDING pension/OPEB/compensated absences (excluded by debt-type code — reliable). Col F 'Official Total Liabilities' = DIRECT: grand total of the Schedule 09 as filed with SAO (all liabilities incl. pension/OPEB; no pattern matching). WATER/SEWER portion: none identifiable by keyword (may be $0, generically labeled, or held by a separate entity) [REGEX/KEYWORD — IMPRECISE]. W/S keyword=$0: water supplied by Asotin County PUD No.1 (separate entity). | BK5: =BH5 / M5 -> 819.49848 | BL5: ='log(debt) vs log(pop.) normaliz'!H5 -> -0.38414583
A6: Woodland | B6: Longview | C6: Y | E6: public works director, as well as asistant city manager | F6: Y | G6: non gma | H6: *Pending | I6: N | J6: not significant growth, about 1 percent average per anum growth | L6: 37040 | M6: 38230 | N6: =((M6 - L6) / L6) * 100 -> 3.212743 | O6: {=IF(M6 > MEDIAN(_xlfn._xlws.FILTER(M:M, C:C="Y")),"Y","N")} -> Y | P6: =IF(N6 >= 10.15, "Y", "N") -> N | Q6: {=IF(N6 > MEDIAN(_xlfn._xlws.FILTER(N:N, C:C="Y")), "Y", "N")} -> Y | R6: Y | S6: we provide water to beacon hill water sewer district, they are a 15 percent owner, their ditribution is tied to ours we charge them for their distribution. We have an agreement with kelso for high well water. We have an inter connect where they can pull water from our system at a retail rate (whenever we have excess). | T6: N | U6: Y | V6: Y | W6: Yes we have, a little more than 10 years ago we switched to ground wells from surface waters. We expanded our sytem to accomodate for that . | X6: Y | Y6: =IF(C6="N", "", IF(AND(C6="Y", OR(AA6="Y", AB6="Y", AC6="Y", AD6="Y")), "Y", "N")) -> Y | Z6: Y | AA6: N | AB6: Y | AC6: N | AD6: N | AE6: Y | AF6: If its developer driven they pay for it. If its infrastructure investment then we pay it. We issue debt to pay for those large expenses, or we pull from capital reserves. Connection fee for freshwater only, SDC for sewer only. | AG6: N | AH6: N | AI6: Y | AJ6: Y | AK6: N | AL6: N | AM6: N | AN6: N | AO6: Y | AP6: we have sdcs on sewer, no impact, connection charges on water. SDCs are calculated off of ERUs and connection charges are calculated off of size of connection. So charges for freshwater are based on size, sewer is standardized | AQ6: Y (fresh water connection fees) | AR6: Y (sewer SDC) | AS6: N | AT6: N | AU6: Y | AV6: Yes we use a Gis tool. We have an asset management system. Its lucidy, a work order and asset management program (Not gis). As far as our system value, we produce and maintain water and sewer system plans that go into more detail on the value of the system. that is the doc that guides more of our long erm planning. | AW6: Y | AX6: N | AY6: Y | AZ6: Lucidy (asset valuation) | BC6: write here after the car interview | BD6: 145614128 | BE6: FY2024 actual total expenditures, all funds (operating + capital/debt service). Source: WA State Auditor FIT, schedule1AggregationsByGovt (sections 30+35), MCAG 0267. portal.sao.wa.gov/FIT. | BF6: 30408003 | BG6: =BF6 /M6 -> 795.39636 | BH6: 63665714 | BI6: 0 | BJ6: FY2024 Schedule 09 via SAO FIT API (Snapshots/Schedule9s, MCAG 0267). Col E 'Outstanding Debt' = CALCULATED: total LT principal EXCLUDING pension/OPEB/compensated absences (excluded by debt-type code — reliable). Col F 'Official Total Liabilities' = DIRECT: grand total of the Schedule 09 as filed with SAO (all liabilities incl. pension/OPEB; no pattern matching). WATER/SEWER portion: none identifiable by keyword (may be $0, generically labeled, or held by a separate entity) [REGEX/KEYWORD — IMPRECISE]. W/S keyword=$0: city co-owns Mint Farm Regional WTP w/ Beacon Hill W&S District; water debt largely on the regional entity. Verify in ACFR. | BK6: =BH6 / M6 -> 1665.3339 | BL6: ='log(debt) vs log(pop.) normaliz'!H6 -> 0.22066871
A7: Cowlitz | B7: Kelso | C7: N | H7: *Pending | L7: 11960 | M7: 12780 | N7: =((M7 - L7) / L7) * 100 -> 6.8561873 | O7: {=IF(M7 > MEDIAN(_xlfn._xlws.FILTER(M:M, C:C="Y")),"Y","N")} -> Y | P7: =IF(N7 >= 10.15, "Y", "N") -> N | Q7: {=IF(N7 > MEDIAN(_xlfn._xlws.FILTER(N:N, C:C="Y")), "Y", "N")} -> Y | Y7: =IF(C7="N", "", IF(AND(C7="Y", OR(AA7="Y", AB7="Y", AC7="Y", AD7="Y")), "Y", "N")) | BD7: 49960615 | BE7: FY2024 actual total expenditures, all funds (operating + capital/debt service). Source: WA State Auditor FIT, schedule1AggregationsByGovt (sections 30+35), MCAG 0264. portal.sao.wa.gov/FIT. | BF7: 10933802 | BG7: =BF7 /M7 -> 855.54006 | BH7: 18018433 | BI7: 2819084 | BJ7: FY2024 Schedule 09 via SAO FIT API (Snapshots/Schedule9s, MCAG 0264). Col E 'Outstanding Debt' = CALCULATED: total LT principal EXCLUDING pension/OPEB/compensated absences (excluded by debt-type code — reliable). Col F 'Official Total Liabilities' = DIRECT: grand total of the Schedule 09 as filed with SAO (all liabilities incl. pension/OPEB; no pattern matching). WATER/SEWER portion ~$2,819,084 [REGEX/KEYWORD — IMPRECISE: matched on debt-description text only (no fund tag in FIT); approximate]. | BK7: =BH7 / M7 -> 1409.893 | BL7: ='log(debt) vs log(pop.) normaliz'!H7 -> 0.12282095
A8: Cowlitz | B8: Castle Rock | C8: N | H8: *Pending | L8: 2145 | M8: 2465 | N8: =((M8 - L8) / L8) * 100 -> 14.918415 | O8: {=IF(M8 > MEDIAN(_xlfn._xlws.FILTER(M:M, C:C="Y")),"Y","N")} -> Y | P8: =IF(N8 >= 10.15, "Y", "N") -> Y | Q8: {=IF(N8 > MEDIAN(_xlfn._xlws.FILTER(N:N, C:C="Y")), "Y", "N")} -> Y | Y8: =IF(C8="N", "", IF(AND(C8="Y", OR(AA8="Y", AB8="Y", AC8="Y", AD8="Y")), "Y", "N")) | BD8: 7639897 | BE8: FY2024 actual total expenditures, all funds (operating + capital/debt service). Source: WA State Auditor FIT, schedule1AggregationsByGovt (sections 30+35), MCAG 0260. portal.sao.wa.gov/FIT. | BF8: 5766734 | BG8: =BF8 /M8 -> 2339.4458 | BH8: 6060122 | BI8: 286841 | BJ8: FY2024 Schedule 09 via SAO FIT API (Snapshots/Schedule9s, MCAG 0260). Col E 'Outstanding Debt' = CALCULATED: total LT principal EXCLUDING pension/OPEB/compensated absences (excluded by debt-type code — reliable). Col F 'Official Total Liabilities' = DIRECT: grand total of the Schedule 09 as filed with SAO (all liabilities incl. pension/OPEB; no pattern matching). WATER/SEWER portion ~$286,841 [REGEX/KEYWORD — IMPRECISE: matched on debt-description text only (no fund tag in FIT); approximate]. | BK8: =BH8 / M8 -> 2458.4673 | BL8: ='log(debt) vs log(pop.) normaliz'!H8 -> 0.78197168
A9: Cowlitz | B9: Woodland | C9: Y | F9: Y | G9: pending status for GMA. | H9: *Pending | I9: Y | J9: Yes. | K9: Woodland straddles Cowlitz/Clark; figures are full-city totals | L9: 5695 | M9: 6575 | N9: =((M9 - L9) / L9) * 100 -> 15.452151 | O9: {=IF(M9 > MEDIAN(_xlfn._xlws.FILTER(M:M, C:C="Y")),"Y","N")} -> Y | P9: =IF(N9 >= 10.15, "Y", "N") -> Y | Q9: {=IF(N9 > MEDIAN(_xlfn._xlws.FILTER(N:N, C:C="Y")), "Y", "N")} -> Y | R9: Y | S9: We do service for a small housing development in clark county | T9: N | U9: N | V9: Y | W9: City of woodland has not done any internal expansion, but residential has (for connections and water sewage infrastructure). The water main is private, they then relinquish infrastructure to our department. They charge SDCs to new developers, we do not. | X9: N | Y9: =IF(C9="N", "", IF(AND(C9="Y", OR(AA9="Y", AB9="Y", AC9="Y", AD9="Y")), "Y", "N")) -> Y | Z9: Y | AA9: N | AB9: N | AC9: N | AD9: Y | AE9: N | AF9: City does not pay for any of the expansion costs, all developer driven | AG9: N | AH9: N/A | AI9: N/A | AJ9: N/A | AK9: N/A | AL9: N/A | AM9: N/A | AN9: N/A | AO9: N/A | AP9: (they don’t handle these, so I didn’t ask because its not their jurisdiction in this case) | AQ9: N/A | AR9: N/A | AS9: N/A | AT9: N/A | AU9: Y | AV9: We use GIS ezeree. We are looking to update. We just use it informationally, no asset valuation, unless its sewer INI | AW9: Y | AX9: N | AY9: N | BA9: would recommend to look at capital improvement list, what are the current system constraints? Put a denomination next to what projects are most importanmt. Every 5 years we do a third party review for capital improvement projects. FCJ they come in as a third party. | BC9: Good | BD9: 18142398 | BE9: FY2024 actual total expenditures, all funds (operating + capital/debt service). Source: WA State Auditor FIT, schedule1AggregationsByGovt (sections 30+35), MCAG 0271. portal.sao.wa.gov/FIT. | BF9: 5778202 | BG9: =BF9 /M9 -> 878.81399 | BH9: 7023570 | BI9: 294582 | BJ9: FY2024 Schedule 09 via SAO FIT API (Snapshots/Schedule9s, MCAG 0271). Col E 'Outstanding Debt' = CALCULATED: total LT principal EXCLUDING pension/OPEB/compensated absences (excluded by debt-type code — reliable). Col F 'Official Total Liabilities' = DIRECT: grand total of the Schedule 09 as filed with SAO (all liabilities incl. pension/OPEB; no pattern matching). WATER/SEWER portion ~$294,582 [REGEX/KEYWORD — IMPRECISE: matched on debt-description text only (no fund tag in FIT); approximate]. | BK9: =BH9 / M9 -> 1068.2236 | BL9: ='log(debt) vs log(pop.) normaliz'!H9 -> -0.11304852
A10: Cowlitz | B10: Kalama | C10: N | H10: *Pending | L10: 2430 | M10: 3160 | N10: =((M10 - L10) / L10) * 100 -> 30.041152 | O10: {=IF(M10 > MEDIAN(_xlfn._xlws.FILTER(M:M, C:C="Y")),"Y","N")} -> Y | P10: =IF(N10 >= 10.15, "Y", "N") -> Y | Q10: {=IF(N10 > MEDIAN(_xlfn._xlws.FILTER(N:N, C:C="Y")), "Y", "N")} -> Y | Y10: =IF(C10="N", "", IF(AND(C10="Y", OR(AA10="Y", AB10="Y", AC10="Y", AD10="Y")), "Y", "N")) | BD10: 10910954 | BE10: FY2024 actual total expenditures, all funds (operating + capital/debt service). Source: WA State Auditor FIT, schedule1AggregationsByGovt (sections 30+35), MCAG 0262. portal.sao.wa.gov/FIT. | BF10: 3807013 | BG10: =BF10 /M10 -> 1204.7509 | BH10: 4170942 | BI10: 1177934 | BJ10: FY2024 Schedule 09 via SAO FIT API (Snapshots/Schedule9s, MCAG 0262). Col E 'Outstanding Debt' = CALCULATED: total LT principal EXCLUDING pension/OPEB/compensated absences (excluded by debt-type code — reliable). Col F 'Official Total Liabilities' = DIRECT: grand total of the Schedule 09 as filed with SAO (all liabilities incl. pension/OPEB; no pattern matching). WATER/SEWER portion ~$1,177,934 [REGEX/KEYWORD — IMPRECISE: matched on debt-description text only (no fund tag in FIT); approximate]. | BK10: =BH10 / M10 -> 1319.9184 | BL10: ='log(debt) vs log(pop.) normaliz'!H10 -> 0.1444388
A11: Ferry | B11: Republic | C11: Y | E11: Public works director, Republic | F11: N | G11: Doesn’t know, new to position. [they are ___] | H11: *Partially Planning | I11: N | J11: No | K11: *Ferry County is the only "voluntary GMA" county that later opted out (RCW 36.70A.040(2)(b)) | L11: 1100 | M11: 1005 | N11: =((M11 - L11) / L11) * 100 -> -8.6363636 | O11: {=IF(M11 > MEDIAN(_xlfn._xlws.FILTER(M:M, C:C="Y")),"Y","N")} -> N | P11: =IF(N11 >= 10.15, "Y", "N") -> N | Q11: {=IF(N11 > MEDIAN(_xlfn._xlws.FILTER(N:N, C:C="Y")), "Y", "N")} -> N | R11: N | S11: No | T11: N | U11: N | V11: N | W11: No, using about 60% of capacity | X11: N | Y11: =IF(C11="N", "", IF(AND(C11="Y", OR(AA11="Y", AB11="Y", AC11="Y", AD11="Y")), "Y", "N")) -> N | Z11: N/A | AA11: N/A | AB11: N/A | AC11: N/A | AD11: N/A | AE11: Y | AF11: Engineering firm, in spokane, they do it. We get charged for their development. County tax vbas, hotel motel tax, typically sewer water rates pay for everything. | AG11: Y | AH11: N | AI11: N | AJ11: N | AK11: N | AL11: N | AM11: N | AN11: Y | AO11: N/A | AQ11: N/A | AR11: N/A | AS11: N/A | AT11: N/A | AU11: Y | AV11: Just recently got GIS set up. Primarily for locating, no bluetooth meters. Only had it about 8-9 months. Mainly for locating valves for streets in valves. We pay a monthly, only 3 grand payment, 1300 residence 600 meters. Poorest county in state. | AW11: Y | AX11: N | AY11: N | BA11: Been public works director for year in a half 60 with 40 years in construction, think its helped a lot with problem solving skills. 125 year old town, 6-7 years ago case of embezzlment, now we get audited every year. Young mayor, fantastic city clerk. main source of leaks is steel pipes, pumpibng 130m gallons a year, wasting 27%. 6 inch pvc, wasting a lot of money on contractors. | BC11: All went well, first survey. | BD11: 4919773 | BE11: FY2024 actual total expenditures, all funds (operating + capital/debt service). Source: WA State Auditor FIT, schedule1AggregationsByGovt (sections 30+35), MCAG 0284. portal.sao.wa.gov/FIT. | BF11: 400766 | BG11: =BF11 /M11 -> 398.77214 | BH11: 432112 | BI11: 297105 | BJ11: FY2024 Schedule 09 via SAO FIT API (Snapshots/Schedule9s, MCAG 0284). Col E 'Outstanding Debt' = CALCULATED: total LT principal EXCLUDING pension/OPEB/compensated absences (excluded by debt-type code — reliable). Col F 'Official Total Liabilities' = DIRECT: grand total of the Schedule 09 as filed with SAO (all liabilities incl. pension/OPEB; no pattern matching). WATER/SEWER portion ~$297,105 [REGEX/KEYWORD — IMPRECISE: matched on debt-description text only (no fund tag in FIT); approximate]. | BK11: =BH11 / M11 -> 429.96219 | BL11: ='log(debt) vs log(pop.) normaliz'!H11 -> -0.90540152
A12: Grays Harbor | B12: Aberdeen | C12: Y | E12: Public works director of Aberdeen | F12: N | G12: [They are ___] | H12: Partially Planning | I12: N | J12: Maybe 500 new ppl, lots of new development though, around 40 new projects | L12: 16850 | M12: 17100 | N12: =((M12 - L12) / L12) * 100 -> 1.4836795 | O12: {=IF(M12 > MEDIAN(_xlfn._xlws.FILTER(M:M, C:C="Y")),"Y","N")} -> Y | P12: =IF(N12 >= 10.15, "Y", "N") -> N | Q12: {=IF(N12 > MEDIAN(_xlfn._xlws.FILTER(N:N, C:C="Y")), "Y", "N")} -> N | R12: N | S12: not currently, in negotiation to buy / be in same contract as cosmopolis' water system | T12: N | U12: N | V12: N | W12: No. | X12: N | Y12: =IF(C12="N", "", IF(AND(C12="Y", OR(AA12="Y", AB12="Y", AC12="Y", AD12="Y")), "Y", "N")) -> N | Z12: N/A | AA12: N/A | AB12: N/A | AC12: N/A | AD12: N/A | AE12: Y | AF12: Future growth covered completely by rates. About 2,000 acres of timber, town considered a small landowner. Can harvest every other year. We are upgrading roads to support this. Planning on selling and using timber to draw interest which would then go to water, but could be used more generally. They do SDC by meter, its about 35 hundred dollars. Depends on size of meter. No latecomers agreement | AG12: Y | AH12: N | AI12: N | AJ12: Y | AK12: N | AL12: N | AM12: N | AN12: Y | AO12: Y | AP12: primarily based on meter size. 6 inch lines for fire dept., developers pay in full for additional costs associated with fire protection developments if necessary. | AQ12: Y | AR12: N | AS12: N | AT12: N | AU12: Y | AV12: yes, we use it for location. Havent used for asset valuation yet, but they can. If meter is not used for 6 months, its worth more to take it out. Not an expert on this. AMES software is more for the valuation stuff | AW12: Y | AX12: N | AY12: Y | AZ12: AMES (asset valuation) | BC12: Went well, second survey | BD12: 62604391 | BE12: FY2024 actual total expenditures, all funds (operating + capital/debt service). Source: WA State Auditor FIT, schedule1AggregationsByGovt (sections 30+35), MCAG 0331. portal.sao.wa.gov/FIT. | BF12: 10472462 | BG12: =BF12 /M12 -> 612.42468 | BH12: 38656768 | BI12: 9764209 | BJ12: FY2024 Schedule 09 via SAO FIT API (Snapshots/Schedule9s, MCAG 0331). Col E 'Outstanding Debt' = CALCULATED: total LT principal EXCLUDING pension/OPEB/compensated absences (excluded by debt-type code — reliable). Col F 'Official Total Liabilities' = DIRECT: grand total of the Schedule 09 as filed with SAO (all liabilities incl. pension/OPEB; no pattern matching). WATER/SEWER portion ~$9,764,209 [REGEX/KEYWORD — IMPRECISE: matched on debt-description text only (no fund tag in FIT); approximate]. Debt overwhelmingly water/sewer (8->12 MGD Water Reclamation Plant + WWTP/reservoir DOE/DOH loans). | BK12: =BH12 / M12 -> 2260.6297 | BL12: ='log(debt) vs log(pop.) normaliz'!H12 -> 0.57670278
A13: Grays Harbor | B13: Hoquiam | C13: N | H13: Partially Planning | L13: 8625 | M13: 8800 | N13: =((M13 - L13) / L13) * 100 -> 2.0289855 | O13: {=IF(M13 > MEDIAN(_xlfn._xlws.FILTER(M:M, C:C="Y")),"Y","N")} -> Y | P13: =IF(N13 >= 10.15, "Y", "N") -> N | Q13: {=IF(N13 > MEDIAN(_xlfn._xlws.FILTER(N:N, C:C="Y")), "Y", "N")} -> N | Y13: =IF(C13="N", "", IF(AND(C13="Y", OR(AA13="Y", AB13="Y", AC13="Y", AD13="Y")), "Y", "N")) | BD13: 35544582 | BE13: FY2024 actual total expenditures, all funds (operating + capital/debt service). Source: WA State Auditor FIT, schedule1AggregationsByGovt (sections 30+35), MCAG 0340. portal.sao.wa.gov/FIT. | BF13: 14189572 | BG13: =BF13 /M13 -> 1612.4514 | BH13: 25208098 | BI13: 11630621 | BJ13: FY2024 Schedule 09 via SAO FIT API (Snapshots/Schedule9s, MCAG 0340). Col E 'Outstanding Debt' = CALCULATED: total LT principal EXCLUDING pension/OPEB/compensated absences (excluded by debt-type code — reliable). Col F 'Official Total Liabilities' = DIRECT: grand total of the Schedule 09 as filed with SAO (all liabilities incl. pension/OPEB; no pattern matching). WATER/SEWER portion ~$11,630,621 [REGEX/KEYWORD — IMPRECISE: matched on debt-description text only (no fund tag in FIT); approximate]. | BK13: =BH13 / M13 -> 2864.5566 | BL13: ='log(debt) vs log(pop.) normaliz'!H13 -> 0.8551027
A14: Grays Harbor | B14: Ocean Shores | C14: N | H14: Partially Planning | L14: 5880 | M14: 7630 | N14: =((M14 - L14) / L14) * 100 -> 29.761905 | O14: {=IF(M14 > MEDIAN(_xlfn._xlws.FILTER(M:M, C:C="Y")),"Y","N")} -> Y | P14: =IF(N14 >= 10.15, "Y", "N") -> Y | Q14: {=IF(N14 > MEDIAN(_xlfn._xlws.FILTER(N:N, C:C="Y")), "Y", "N")} -> Y | Y14: =IF(C14="N", "", IF(AND(C14="Y", OR(AA14="Y", AB14="Y", AC14="Y", AD14="Y")), "Y", "N")) | BD14: 30517848 | BE14: FY2024 actual total expenditures, all funds (operating + capital/debt service). Source: WA State Auditor FIT, schedule1AggregationsByGovt (sections 30+35), MCAG 0352. portal.sao.wa.gov/FIT. | BF14: 10179412 | BG14: =BF14 /M14 -> 1334.13 | BH14: 14252693 | BI14: 1298157 | BJ14: FY2024 Schedule 09 via SAO FIT API (Snapshots/Schedule9s, MCAG 0352). Col E 'Outstanding Debt' = CALCULATED: total LT principal EXCLUDING pension/OPEB/compensated absences (excluded by debt-type code — reliable). Col F 'Official Total Liabilities' = DIRECT: grand total of the Schedule 09 as filed with SAO (all liabilities incl. pension/OPEB; no pattern matching). WATER/SEWER portion ~$1,298,157 [REGEX/KEYWORD — IMPRECISE: matched on debt-description text only (no fund tag in FIT); approximate]. | BK14: =BH14 / M14 -> 1867.9807 | BL14: ='log(debt) vs log(pop.) normaliz'!H14 -> 0.43648713
A15: Grays Harbor | B15: Montesano | C15: N | H15: Partially Planning | L15: 4075 | M15: 4135 | N15: =((M15 - L15) / L15) * 100 -> 1.4723926 | O15: {=IF(M15 > MEDIAN(_xlfn._xlws.FILTER(M:M, C:C="Y")),"Y","N")} -> Y | P15: =IF(N15 >= 10.15, "Y", "N") -> N | Q15: {=IF(N15 > MEDIAN(_xlfn._xlws.FILTER(N:N, C:C="Y")), "Y", "N")} -> N | Y15: =IF(C15="N", "", IF(AND(C15="Y", OR(AA15="Y", AB15="Y", AC15="Y", AD15="Y")), "Y", "N")) | BD15: 12726205 | BE15: FY2024 actual total expenditures, all funds (operating + capital/debt service). Source: WA State Auditor FIT, schedule1AggregationsByGovt (sections 30+35), MCAG 0347. portal.sao.wa.gov/FIT. | BF15: 2072244 | BG15: =BF15 /M15 -> 501.14728 | BH15: 3976430 | BI15: 78947 | BJ15: FY2024 Schedule 09 via SAO FIT API (Snapshots/Schedule9s, MCAG 0347). Col E 'Outstanding Debt' = CALCULATED: total LT principal EXCLUDING pension/OPEB/compensated absences (excluded by debt-type code — reliable). Col F 'Official Total Liabilities' = DIRECT: grand total of the Schedule 09 as filed with SAO (all liabilities incl. pension/OPEB; no pattern matching). WATER/SEWER portion ~$78,947 [REGEX/KEYWORD — IMPRECISE: matched on debt-description text only (no fund tag in FIT); approximate]. | BK15: =BH15 / M15 -> 961.65175 | BL15: ='log(debt) vs log(pop.) normaliz'!H15 -> -0.18908544
A16: Grays Harbor | B16: Elma | C16: Y | E16: Public works director of Elma | F16: Y | G16: non growth management act | H16: Partially Planning | I16: N | J16: not gone up much, still around 35 hundred people | K16: Survey had ~3,500 / ~3,500 (2015 was actually 3,135; 2025 is 3,535) | L16: 3130 | M16: 3505 | N16: =((M16 - L16) / L16) * 100 -> 11.980831 | O16: {=IF(M16 > MEDIAN(_xlfn._xlws.FILTER(M:M, C:C="Y")),"Y","N")} -> Y | P16: =IF(N16 >= 10.15, "Y", "N") -> Y | Q16: {=IF(N16 > MEDIAN(_xlfn._xlws.FILTER(N:N, C:C="Y")), "Y", "N")} -> Y | R16: N | S16: No other towns, do provide outside of city limits though within where the service area limits extend. | T16: N | U16: N | V16: Y | W16: mostly to accommodate some development, no water rights expansion, mostly connections | X16: N | Y16: =IF(C16="N", "", IF(AND(C16="Y", OR(AA16="Y", AB16="Y", AC16="Y", AD16="Y")), "Y", "N")) -> N | Z16: Y | AA16: N | AB16: N | AC16: N | AD16: N | AE16: Y | AF16: couple different ways. Contributions to our capital accounts. Connection fees. We seek out grants from state revolving. Try to get as much free money as we can. | AG16: N | AH16: N | AI16: Y | AJ16: N | AK16: Y | AL16: N | AM16: Y | AN16: N | AO16: Y | AP16: Was calculated before I took this position. Now we just do yearly increases for inflation. Normally you would figure out operating costs divided by each connection, then charge that for each new connection. These are capital facility fees | AQ16: N | AR16: N | AS16: Y | AT16: Y | AU16: Y | AV16: Currently in development of GIS. Will use both for billing and for geographical understanding of the meters | AW16: Y | AX16: Y | AY16: N | BA16: Something to take into account in general, most of that expansion is on the developer to cover in terms of fees. If infrastructre isnt there the developer pays. Especially happens in small municipalities. | BC16: fourth done. | BD16: 7995149 | BE16: FY2024 actual total expenditures, all funds (operating + capital/debt service). Source: WA State Auditor FIT, schedule1AggregationsByGovt (sections 30+35), MCAG 0338. portal.sao.wa.gov/FIT. | BF16: 437395 | BG16: =BF16 /M16 -> 124.79173 | BH16: 1840144 | BI16: 0 | BJ16: FY2024 Schedule 09 via SAO FIT API (Snapshots/Schedule9s, MCAG 0338). Col E 'Outstanding Debt' = CALCULATED: total LT principal EXCLUDING pension/OPEB/compensated absences (excluded by debt-type code — reliable). Col F 'Official Total Liabilities' = DIRECT: grand total of the Schedule 09 as filed with SAO (all liabilities incl. pension/OPEB; no pattern matching). WATER/SEWER portion: none identifiable by keyword (may be $0, generically labeled, or held by a separate entity) [REGEX/KEYWORD — IMPRECISE]. | BK16: =BH16 / M16 -> 525.00542 | BL16: ='log(debt) vs log(pop.) normaliz'!H16 -> -0.78397098
A17: Grays Harbor | B17: Westport | C17: N | H17: Partially Planning | L17: 2110 | M17: 2325 | N17: =((M17 - L17) / L17) * 100 -> 10.189573 | O17: {=IF(M17 > MEDIAN(_xlfn._xlws.FILTER(M:M, C:C="Y")),"Y","N")} -> Y | P17: =IF(N17 >= 10.15, "Y", "N") -> Y | Q17: {=IF(N17 > MEDIAN(_xlfn._xlws.FILTER(N:N, C:C="Y")), "Y", "N")} -> Y | Y17: =IF(C17="N", "", IF(AND(C17="Y", OR(AA17="Y", AB17="Y", AC17="Y", AD17="Y")), "Y", "N")) | BD17: 13777291 | BE17: FY2024 actual total expenditures, all funds (operating + capital/debt service). Source: WA State Auditor FIT, schedule1AggregationsByGovt (sections 30+35), MCAG 0355. portal.sao.wa.gov/FIT. | BF17: 12636881 | BG17: =BF17 /M17 -> 5435.2176 | BH17: 13565568 | BI17: 5368311 | BJ17: FY2024 Schedule 09 via SAO FIT API (Snapshots/Schedule9s, MCAG 0355). Col E 'Outstanding Debt' = CALCULATED: total LT principal EXCLUDING pension/OPEB/compensated absences (excluded by debt-type code — reliable). Col F 'Official Total Liabilities' = DIRECT: grand total of the Schedule 09 as filed with SAO (all liabilities incl. pension/OPEB; no pattern matching). WATER/SEWER portion ~$5,368,311 [REGEX/KEYWORD — IMPRECISE: matched on debt-description text only (no fund tag in FIT); approximate]. | BK17: =BH17 / M17 -> 5834.6529 | BL17: ='log(debt) vs log(pop.) normaliz'!H17 -> 1.6499124
A18: Grays Harbor | B18: Cosmopolis | C18: N | H18: Partially Planning | L18: 1645 | M18: 1680 | N18: =((M18 - L18) / L18) * 100 -> 2.1276596 | O18: {=IF(M18 > MEDIAN(_xlfn._xlws.FILTER(M:M, C:C="Y")),"Y","N")} -> N | P18: =IF(N18 >= 10.15, "Y", "N") -> N | Q18: {=IF(N18 > MEDIAN(_xlfn._xlws.FILTER(N:N, C:C="Y")), "Y", "N")} -> N | Y18: =IF(C18="N", "", IF(AND(C18="Y", OR(AA18="Y", AB18="Y", AC18="Y", AD18="Y")), "Y", "N")) | BD18: 5923178 | BE18: FY2024 actual total expenditures, all funds (operating + capital/debt service). Source: WA State Auditor FIT, schedule1AggregationsByGovt (sections 30+35), MCAG 0336. portal.sao.wa.gov/FIT. | BF18: 3233192 | BG18: =BF18 /M18 -> 1924.519 | BH18: 3400333 | BI18: 349428 | BJ18: FY2024 Schedule 09 via SAO FIT API (Snapshots/Schedule9s, MCAG 0336). Col E 'Outstanding Debt' = CALCULATED: total LT principal EXCLUDING pension/OPEB/compensated absences (excluded by debt-type code — reliable). Col F 'Official Total Liabilities' = DIRECT: grand total of the Schedule 09 as filed with SAO (all liabilities incl. pension/OPEB; no pattern matching). WATER/SEWER portion ~$349,428 [REGEX/KEYWORD — IMPRECISE: matched on debt-description text only (no fund tag in FIT); approximate]. | BK18: =BH18 / M18 -> 2024.0077 | BL18: ='log(debt) vs log(pop.) normaliz'!H18 -> 0.61153861
A19: Klickitat | B19: Goldendale | C19: N | H19: Partially Planning | L19: 3420 | M19: 3515 | N19: =((M19 - L19) / L19) * 100 -> 2.7777778 | O19: {=IF(M19 > MEDIAN(_xlfn._xlws.FILTER(M:M, C:C="Y")),"Y","N")} -> Y | P19: =IF(N19 >= 10.15, "Y", "N") -> N | Q19: {=IF(N19 > MEDIAN(_xlfn._xlws.FILTER(N:N, C:C="Y")), "Y", "N")} -> N | Y19: =IF(C19="N", "", IF(AND(C19="Y", OR(AA19="Y", AB19="Y", AC19="Y", AD19="Y")), "Y", "N")) | BD19: 10271678 | BE19: FY2024 actual total expenditures, all funds (operating + capital/debt service). Source: WA State Auditor FIT, schedule1AggregationsByGovt (sections 30+35), MCAG 0479. portal.sao.wa.gov/FIT. | BF19: 9246237 | BG19: =BF19 /M19 -> 2630.5084 | BH19: 10136406 | BI19: 5593718 | BJ19: FY2024 Schedule 09 via SAO FIT API (Snapshots/Schedule9s, MCAG 0479). Col E 'Outstanding Debt' = CALCULATED: total LT principal EXCLUDING pension/OPEB/compensated absences (excluded by debt-type code — reliable). Col F 'Official Total Liabilities' = DIRECT: grand total of the Schedule 09 as filed with SAO (all liabilities incl. pension/OPEB; no pattern matching). WATER/SEWER portion ~$5,593,718 [REGEX/KEYWORD — IMPRECISE: matched on debt-description text only (no fund tag in FIT); approximate]. | BK19: =BH19 / M19 -> 2883.757 | BL19: ='log(debt) vs log(pop.) normaliz'!H19 -> 0.91929115
A20: Klickitat | B20: White Salmon | C20: N | H20: Partially Planning | L20: 2315 | M20: 2550 | N20: =((M20 - L20) / L20) * 100 -> 10.151188 | O20: {=IF(M20 > MEDIAN(_xlfn._xlws.FILTER(M:M, C:C="Y")),"Y","N")} -> Y | P20: =IF(N20 >= 10.15, "Y", "N") -> Y | Q20: {=IF(N20 > MEDIAN(_xlfn._xlws.FILTER(N:N, C:C="Y")), "Y", "N")} -> Y | Y20: =IF(C20="N", "", IF(AND(C20="Y", OR(AA20="Y", AB20="Y", AC20="Y", AD20="Y")), "Y", "N")) | BD20: 11885246 | BE20: FY2024 actual total expenditures, all funds (operating + capital/debt service). Source: WA State Auditor FIT, schedule1AggregationsByGovt (sections 30+35), MCAG 0481. portal.sao.wa.gov/FIT. | BF20: 9502535 | BG20: =BF20 /M20 -> 3726.4843 | BH20: 10849934 | BI20: 929624 | BJ20: FY2024 Schedule 09 via SAO FIT API (Snapshots/Schedule9s, MCAG 0481). Col E 'Outstanding Debt' = CALCULATED: total LT principal EXCLUDING pension/OPEB/compensated absences (excluded by debt-type code — reliable). Col F 'Official Total Liabilities' = DIRECT: grand total of the Schedule 09 as filed with SAO (all liabilities incl. pension/OPEB; no pattern matching). WATER/SEWER portion ~$929,624 [REGEX/KEYWORD — IMPRECISE: matched on debt-description text only (no fund tag in FIT); approximate]. $6M DWSRF loan (Contract DWL31566-0) for Transmission Main Phase 2B. | BK20: =BH20 / M20 -> 4254.8761 | BL20: ='log(debt) vs log(pop.) normaliz'!H20 -> 1.3283748
A21: Klickitat | B21: Bingen | C21: N | H21: Partially Planning | L21: 730 | M21: 780 | N21: =((M21 - L21) / L21) * 100 -> 6.8493151 | O21: {=IF(M21 > MEDIAN(_xlfn._xlws.FILTER(M:M, C:C="Y")),"Y","N")} -> N | P21: =IF(N21 >= 10.15, "Y", "N") -> N | Q21: {=IF(N21 > MEDIAN(_xlfn._xlws.FILTER(N:N, C:C="Y")), "Y", "N")} -> Y | Y21: =IF(C21="N", "", IF(AND(C21="Y", OR(AA21="Y", AB21="Y", AC21="Y", AD21="Y")), "Y", "N")) | BD21: 4933703 | BE21: FY2024 actual total expenditures, all funds (operating + capital/debt service). Source: WA State Auditor FIT, schedule1AggregationsByGovt (sections 30+35), MCAG 0477. portal.sao.wa.gov/FIT. | BF21: 4945198 | BG21: =BF21 /M21 -> 6339.9974 | BH21: 5049557 | BI21: 4934844 | BJ21: FY2024 Schedule 09 via SAO FIT API (Snapshots/Schedule9s, MCAG 0477). Col E 'Outstanding Debt' = CALCULATED: total LT principal EXCLUDING pension/OPEB/compensated absences (excluded by debt-type code — reliable). Col F 'Official Total Liabilities' = DIRECT: grand total of the Schedule 09 as filed with SAO (all liabilities incl. pension/OPEB; no pattern matching). WATER/SEWER portion ~$4,934,844 [REGEX/KEYWORD — IMPRECISE: matched on debt-description text only (no fund tag in FIT); approximate]. | BK21: =BH21 / M21 -> 6473.791 | BL21: ='log(debt) vs log(pop.) normaliz'!H21 -> 1.8223006
A22: Lincoln | B22: Davenport | C22: Y | E22: Public Works director for Davenport | F22: NR | G22: (didn’t ask), Not Recorded (NR) | H22: Partially Planning | I22: Y | J22: Had a good amount of people move here for political reasons during and after COVID. usually issue around 100 "right of way"/ "approach" permits a year, which is fairly limited. 70 percent of the land is farm land, very large county, bigger than rhode island or delaware, only around 1,250 people | K22: Survey had 1,250 for current — incorrect; actual OFM 2025 is 1,720 | L22: 1685 | M22: 1730 | N22: =((M22 - L22) / L22) * 100 -> 2.6706231 | O22: {=IF(M22 > MEDIAN(_xlfn._xlws.FILTER(M:M, C:C="Y")),"Y","N")} -> N | P22: =IF(N22 >= 10.15, "Y", "N") -> N | Q22: {=IF(N22 > MEDIAN(_xlfn._xlws.FILTER(N:N, C:C="Y")), "Y", "N")} -> N | R22: N | S22: We do not sell water to other towns. | T22: N | U22: N | V22: N | W22: This town does not have a utilities system for freshwater in the traditional sense (therefore they never are the ones dealing with infrastructure expansions directly). The health department deals with the Sewage. We do deal with irrigation. We franchise with a utilities / engineering corp. that privately owns the water infrastructure. Franchising is working with a contractor under contract to do all work within a county right of way, good for 10 years. THIS TOWN IS AN OUTLIER AND SHOULD BE MARKED AS SUCH. | X22: N | Y22: =IF(C22="N", "", IF(AND(C22="Y", OR(AA22="Y", AB22="Y", AC22="Y", AD22="Y")), "Y", "N")) -> N | Z22: N/A | AA22: N/A | AB22: N/A | AC22: N/A | AD22: N/A | AE22: Y | AF22: We connect development to the private water network via "approaches" on a case by case basis. Piping size is simply based on what is best for the surrounding area (making sure we arent erroding any roads). We charge a "right of way fee" for new approaches based on the type of development ($50 for farmers $100 for residential, $150 for businesses rough numbers) | AG22: N | AH22: N | AI22: N | AJ22: N | AK22: N | AL22: N | AM22: N | AN22: Y | AU22: N | AV22: No GIS tool, because there are no meters | AW22: N/A | AX22: N/A | AY22: N/A | AZ22: N/A | BC22: Survey was not suited to the town's situation. May need to circle back on this county due to how its lack of public utilities district. | BD22: 3782651 | BE22: FY2024 actual total expenditures, all funds (operating + capital/debt service). Source: WA State Auditor FIT, schedule1AggregationsByGovt (sections 30+35), MCAG 0508. portal.sao.wa.gov/FIT. | BF22: 315000 | BG22: =BF22 /M22 -> 182.08092 | BH22: 461657 | BI22: 0 | BJ22: FY2024 Schedule 09 via SAO FIT API (Snapshots/Schedule9s, MCAG 0508). Col E 'Outstanding Debt' = CALCULATED: total LT principal EXCLUDING pension/OPEB/compensated absences (excluded by debt-type code — reliable). Col F 'Official Total Liabilities' = DIRECT: grand total of the Schedule 09 as filed with SAO (all liabilities incl. pension/OPEB; no pattern matching). WATER/SEWER portion: none identifiable by keyword (may be $0, generically labeled, or held by a separate entity) [REGEX/KEYWORD — IMPRECISE]. | BK22: =BH22 / M22 -> 266.85376 | BL22: ='log(debt) vs log(pop.) normaliz'!H22 -> -1.4164333
A23: Lincoln | B23: Odessa | C23: N | H23: Partially Planning | L23: 900 | M23: 895 | N23: =((M23 - L23) / L23) * 100 -> -0.55555556 | O23: {=IF(M23 > MEDIAN(_xlfn._xlws.FILTER(M:M, C:C="Y")),"Y","N")} -> N | P23: =IF(N23 >= 10.15, "Y", "N") -> N | Q23: {=IF(N23 > MEDIAN(_xlfn._xlws.FILTER(N:N, C:C="Y")), "Y", "N")} -> N | Y23: =IF(C23="N", "", IF(AND(C23="Y", OR(AA23="Y", AB23="Y", AC23="Y", AD23="Y")), "Y", "N")) | BD23: 3728724 | BE23: FY2024 actual total expenditures, all funds (operating + capital/debt service). Source: WA State Auditor FIT, schedule1AggregationsByGovt (sections 30+35), MCAG 0512. portal.sao.wa.gov/FIT. | BF23: 2789157 | BG23: =BF23 /M23 -> 3116.3765 | BH23: 2879663 | BI23: 476275 | BJ23: FY2024 Schedule 09 via SAO FIT API (Snapshots/Schedule9s, MCAG 0512). Col E 'Outstanding Debt' = CALCULATED: total LT principal EXCLUDING pension/OPEB/compensated absences (excluded by debt-type code — reliable). Col F 'Official Total Liabilities' = DIRECT: grand total of the Schedule 09 as filed with SAO (all liabilities incl. pension/OPEB; no pattern matching). WATER/SEWER portion ~$476,275 [REGEX/KEYWORD — IMPRECISE: matched on debt-description text only (no fund tag in FIT); approximate]. | BK23: =BH23 / M23 -> 3217.5006 | BL23: ='log(debt) vs log(pop.) normaliz'!H23 -> 1.1145253
A24: Lincoln | B24: Harrington | C24: N | H24: Partially Planning | L24: 415 | M24: 435 | N24: =((M24 - L24) / L24) * 100 -> 4.8192771 | O24: {=IF(M24 > MEDIAN(_xlfn._xlws.FILTER(M:M, C:C="Y")),"Y","N")} -> N | P24: =IF(N24 >= 10.15, "Y", "N") -> N | Q24: {=IF(N24 > MEDIAN(_xlfn._xlws.FILTER(N:N, C:C="Y")), "Y", "N")} -> Y | Y24: =IF(C24="N", "", IF(AND(C24="Y", OR(AA24="Y", AB24="Y", AC24="Y", AD24="Y")), "Y", "N")) | BD24: 1166193 | BE24: FY2024 actual total expenditures, all funds (operating + capital/debt service). Source: WA State Auditor FIT, schedule1AggregationsByGovt (sections 30+35), MCAG 0510. portal.sao.wa.gov/FIT. | BF24: 27356 | BG24: =BF24 /M24 -> 62.887356 | BH24: 36817 | BI24: 0 | BJ24: FY2024 Schedule 09 via SAO FIT API (Snapshots/Schedule9s, MCAG 0510). Col E 'Outstanding Debt' = CALCULATED: total LT principal EXCLUDING pension/OPEB/compensated absences (excluded by debt-type code — reliable). Col F 'Official Total Liabilities' = DIRECT: grand total of the Schedule 09 as filed with SAO (all liabilities incl. pension/OPEB; no pattern matching). WATER/SEWER portion: none identifiable by keyword (may be $0, generically labeled, or held by a separate entity) [REGEX/KEYWORD — IMPRECISE]. | BK24: =BH24 / M24 -> 84.636782 | BL24: ='log(debt) vs log(pop.) normaliz'!H24 -> -2.4782547
A25: Lincoln | B25: Reardan | C25: N | H25: Partially Planning | L25: 570 | M25: 655 | N25: =((M25 - L25) / L25) * 100 -> 14.912281 | O25: {=IF(M25 > MEDIAN(_xlfn._xlws.FILTER(M:M, C:C="Y")),"Y","N")} -> N | P25: =IF(N25 >= 10.15, "Y", "N") -> Y | Q25: {=IF(N25 > MEDIAN(_xlfn._xlws.FILTER(N:N, C:C="Y")), "Y", "N")} -> Y | Y25: =IF(C25="N", "", IF(AND(C25="Y", OR(AA25="Y", AB25="Y", AC25="Y", AD25="Y")), "Y", "N")) | BD25: 2469620 | BE25: FY2024 actual total expenditures, all funds (operating + capital/debt service). Source: WA State Auditor FIT, schedule1AggregationsByGovt (sections 30+35), MCAG 0514. portal.sao.wa.gov/FIT. | BF25: 382742 | BG25: =BF25 /M25 -> 584.33893 | BH25: 407362 | BI25: 0 | BJ25: FY2024 Schedule 09 via SAO FIT API (Snapshots/Schedule9s, MCAG 0514). Col E 'Outstanding Debt' = CALCULATED: total LT principal EXCLUDING pension/OPEB/compensated absences (excluded by debt-type code — reliable). Col F 'Official Total Liabilities' = DIRECT: grand total of the Schedule 09 as filed with SAO (all liabilities incl. pension/OPEB; no pattern matching). WATER/SEWER portion: none identifiable by keyword (may be $0, generically labeled, or held by a separate entity) [REGEX/KEYWORD — IMPRECISE]. | BK25: =BH25 / M25 -> 621.92672 | BL25: ='log(debt) vs log(pop.) normaliz'!H25 -> -0.50944934
A26: Lincoln | B26: Wilbur | C26: Y | E26: clerk treasurer, Melissa Bulger | F26: Y | G26: Partial planning | H26: Partially Planning | I26: N | J26: No. Very minimal growth | L26: 875 | M26: 900 | N26: =((M26 - L26) / L26) * 100 -> 2.8571429 | O26: {=IF(M26 > MEDIAN(_xlfn._xlws.FILTER(M:M, C:C="Y")),"Y","N")} -> N | P26: =IF(N26 >= 10.15, "Y", "N") -> N | Q26: {=IF(N26 > MEDIAN(_xlfn._xlws.FILTER(N:N, C:C="Y")), "Y", "N")} -> N | R26: N | S26: No | T26: N | U26: N | V26: Y | W26: always hooking up new construction, nothing significant though. New units, new connections, nothing else. | X26: N | Y26: =IF(C26="N", "", IF(AND(C26="Y", OR(AA26="Y", AB26="Y", AC26="Y", AD26="Y")), "Y", "N")) -> N | Z26: Y | AA26: N | AB26: N | AC26: N | AD26: N | AE26: Y | AF26: We implemented an impact fee. They are specifically to go to future expansion in water, sewer and streets. Things are starting to get expensive so they are worth planning for. | AG26: N | AH26: N | AI26: N | AJ26: N | AK26: N | AL26: Y | AM26: N | AN26: N | AO26: N | AP26: We went off of what is similar to the county | AQ26: NR | AR26: NR | AS26: Y | AT26: NR | AU26: Y | AV26: We do have a GIS system, not suited for basic water metering, mostly used for construction. Never used for asset valuation | AW26: N | AX26: N | AY26: N | BA26: When I do the budgetting for water, what we are looking at is how expenditures are chantging over the last year. Anything that we can forsee, like gas prices jumping, anything we think will be an impact we try to add that as a thought process for our budget. | BC26: went well. Interestingly the only partial planning GMA town that utilizes impact fees | BD26: 2158021 | BE26: FY2024 actual total expenditures, all funds (operating + capital/debt service). Source: WA State Auditor FIT, schedule1AggregationsByGovt (sections 30+35), MCAG 0518. portal.sao.wa.gov/FIT. | BF26: 75365 | BG26: =BF26 /M26 -> 83.738889 | BH26: 82353 | BI26: 0 | BJ26: FY2024 Schedule 09 via SAO FIT API (Snapshots/Schedule9s, MCAG 0518). Col E 'Outstanding Debt' = CALCULATED: total LT principal EXCLUDING pension/OPEB/compensated absences (excluded by debt-type code — reliable). Col F 'Official Total Liabilities' = DIRECT: grand total of the Schedule 09 as filed with SAO (all liabilities incl. pension/OPEB; no pattern matching). WATER/SEWER portion: none identifiable by keyword (may be $0, generically labeled, or held by a separate entity) [REGEX/KEYWORD — IMPRECISE]. | BK26: =BH26 / M26 -> 91.503333 | BL26: ='log(debt) vs log(pop.) normaliz'!H26 -> -2.4458085
A27: Okanogan | B27: Omak | C27: Y | F27: N | H27: Partially Planning | I27: N | L27: 4840 | M27: 4980 | N27: =((M27 - L27) / L27) * 100 -> 2.892562 | O27: {=IF(M27 > MEDIAN(_xlfn._xlws.FILTER(M:M, C:C="Y")),"Y","N")} -> Y | P27: =IF(N27 >= 10.15, "Y", "N") -> N | Q27: {=IF(N27 > MEDIAN(_xlfn._xlws.FILTER(N:N, C:C="Y")), "Y", "N")} -> N | R27: N | S27: No | T27: N | U27: N | V27: Y | W27: Developer driven. Just new connections | X27: N | Y27: =IF(C27="N", "", IF(AND(C27="Y", OR(AA27="Y", AB27="Y", AC27="Y", AD27="Y")), "Y", "N")) -> N | Z27: Y | AA27: N | AB27: N | AC27: N | AD27: N | AE27: Y | AF27: Developers develop it to our standards then we take it over. We use development fees for commissions, not sure what it is exactly though (between SDCs and CFCs). | AG27: N | AH27: Y | AI27: N | AJ27: N | AK27: N | AL27: N | AM27: N | AN27: N | AO27: N | AQ27: N/A | AR27: N/A | AS27: N/A | AT27: N/A | AU27: Y | AV27: We use G works for assets, GIS is a part of that too | AW27: Y | AX27: Y | AY27: N | BA27: [very short and to the point] | BC27: went alright, short and to the point | BD27: 19841594 | BE27: FY2024 actual total expenditures, all funds (operating + capital/debt service). Source: WA State Auditor FIT, schedule1AggregationsByGovt (sections 30+35), MCAG 0533. portal.sao.wa.gov/FIT. | BF27: 7519836 | BG27: =BF27 /M27 -> 1510.0072 | BH27: 10183577 | BI27: 1970301 | BJ27: FY2024 Schedule 09 via SAO FIT API (Snapshots/Schedule9s, MCAG 0533). Col E 'Outstanding Debt' = CALCULATED: total LT principal EXCLUDING pension/OPEB/compensated absences (excluded by debt-type code — reliable). Col F 'Official Total Liabilities' = DIRECT: grand total of the Schedule 09 as filed with SAO (all liabilities incl. pension/OPEB; no pattern matching). WATER/SEWER portion ~$1,970,301 [REGEX/KEYWORD — IMPRECISE: matched on debt-description text only (no fund tag in FIT); approximate]. | BK27: =BH27 / M27 -> 2044.895 | BL27: ='log(debt) vs log(pop.) normaliz'!H27 -> 0.55371187
A28: Okanogan | B28: Okanogan (city) | C28: N | H28: Partially Planning | L28: 2595 | M28: 2420 | N28: =((M28 - L28) / L28) * 100 -> -6.743738 | O28: {=IF(M28 > MEDIAN(_xlfn._xlws.FILTER(M:M, C:C="Y")),"Y","N")} -> Y | P28: =IF(N28 >= 10.15, "Y", "N") -> N | Q28: {=IF(N28 > MEDIAN(_xlfn._xlws.FILTER(N:N, C:C="Y")), "Y", "N")} -> N | Y28: =IF(C28="N", "", IF(AND(C28="Y", OR(AA28="Y", AB28="Y", AC28="Y", AD28="Y")), "Y", "N")) | BD28: 6189987 | BE28: FY2024 actual total expenditures, all funds (operating + capital/debt service). Source: WA State Auditor FIT, schedule1AggregationsByGovt (sections 30+35), MCAG 0531. portal.sao.wa.gov/FIT. | BF28: 1310586 | BG28: =BF28 /M28 -> 541.56446 | BH28: 1618092 | BI28: 947727 | BJ28: FY2024 Schedule 09 via SAO FIT API (Snapshots/Schedule9s, MCAG 0531). Col E 'Outstanding Debt' = CALCULATED: total LT principal EXCLUDING pension/OPEB/compensated absences (excluded by debt-type code — reliable). Col F 'Official Total Liabilities' = DIRECT: grand total of the Schedule 09 as filed with SAO (all liabilities incl. pension/OPEB; no pattern matching). WATER/SEWER portion ~$947,727 [REGEX/KEYWORD — IMPRECISE: matched on debt-description text only (no fund tag in FIT); approximate]. | BK28: =BH28 / M28 -> 668.63306 | BL28: ='log(debt) vs log(pop.) normaliz'!H28 -> -0.51893175
A29: Okanogan | B29: Brewster | C29: N | H29: Partially Planning | L29: 2380 | M29: 1995 | N29: =((M29 - L29) / L29) * 100 -> -16.176471 | O29: {=IF(M29 > MEDIAN(_xlfn._xlws.FILTER(M:M, C:C="Y")),"Y","N")} -> Y | P29: =IF(N29 >= 10.15, "Y", "N") -> N | Q29: {=IF(N29 > MEDIAN(_xlfn._xlws.FILTER(N:N, C:C="Y")), "Y", "N")} -> N | Y29: =IF(C29="N", "", IF(AND(C29="Y", OR(AA29="Y", AB29="Y", AC29="Y", AD29="Y")), "Y", "N")) | BD29: 8231324 | BE29: FY2024 actual total expenditures, all funds (operating + capital/debt service). Source: WA State Auditor FIT, schedule1AggregationsByGovt (sections 30+35), MCAG 0523. portal.sao.wa.gov/FIT. | BF29: 4054132 | BG29: =BF29 /M29 -> 2032.1464 | BH29: 5251721 | BI29: 806343 | BJ29: FY2024 Schedule 09 via SAO FIT API (Snapshots/Schedule9s, MCAG 0523). Col E 'Outstanding Debt' = CALCULATED: total LT principal EXCLUDING pension/OPEB/compensated absences (excluded by debt-type code — reliable). Col F 'Official Total Liabilities' = DIRECT: grand total of the Schedule 09 as filed with SAO (all liabilities incl. pension/OPEB; no pattern matching). WATER/SEWER portion ~$806,343 [REGEX/KEYWORD — IMPRECISE: matched on debt-description text only (no fund tag in FIT); approximate]. | BK29: =BH29 / M29 -> 2632.4416 | BL29: ='log(debt) vs log(pop.) normaliz'!H29 -> 0.86360189
A30: Okanogan | B30: Oroville | C30: Y | E30: city superintendent | F30: Y | G30: we are following it but we don’t have to | H30: Partially Planning | I30: N | J30: No | L30: 1700 | M30: 1815 | N30: =((M30 - L30) / L30) * 100 -> 6.7647059 | O30: {=IF(M30 > MEDIAN(_xlfn._xlws.FILTER(M:M, C:C="Y")),"Y","N")} -> N | P30: =IF(N30 >= 10.15, "Y", "N") -> N | Q30: {=IF(N30 > MEDIAN(_xlfn._xlws.FILTER(N:N, C:C="Y")), "Y", "N")} -> Y | R30: N | S30: Provide some to the county but not other towns | T30: N | U30: Y | V30: N | W30: Renewing mainlines. We have a graph that is supposed to run a larger line | X30: N | Y30: =IF(C30="N", "", IF(AND(C30="Y", OR(AA30="Y", AB30="Y", AC30="Y", AD30="Y")), "Y", "N")) -> N | Z30: Y | AA30: N | AB30: N | AC30: N | AD30: N | AE30: Y | AF30: We charge upfront fees (SDC or CFC), Not sure exactly what they are though | AG30: N | AH30: Y | AI30: N | AJ30: N | AK30: N | AL30: N | AM30: N | AN30: N | AO30: N | AP30: Doesn’t know | AQ30: N/A | AR30: N/A | AS30: N/A | AT30: N/A | AU30: Y | AV30: mainly for geographic understanding, not as much for asset valuation | AW30: Y | AX30: N | AY30: N | BC30: Short and to the point | BD30: 4802892 | BE30: FY2024 actual total expenditures, all funds (operating + capital/debt service). Source: WA State Auditor FIT, schedule1AggregationsByGovt (sections 30+35), MCAG 0535. portal.sao.wa.gov/FIT. | BF30: 959289 | BG30: =BF30 /M30 -> 528.53388 | BH30: 1751239 | BI30: 0 | BJ30: FY2024 Schedule 09 via SAO FIT API (Snapshots/Schedule9s, MCAG 0535). Col E 'Outstanding Debt' = CALCULATED: total LT principal EXCLUDING pension/OPEB/compensated absences (excluded by debt-type code — reliable). Col F 'Official Total Liabilities' = DIRECT: grand total of the Schedule 09 as filed with SAO (all liabilities incl. pension/OPEB; no pattern matching). WATER/SEWER portion: none identifiable by keyword (may be $0, generically labeled, or held by a separate entity) [REGEX/KEYWORD — IMPRECISE]. | BK30: =BH30 / M30 -> 964.86997 | BL30: ='log(debt) vs log(pop.) normaliz'!H30 -> -0.13414635
A31: Okanogan | B31: Tonasket | C31: Y | E31: City superintendent | F31: N | H31: Partially Planning | I31: N | J31: No, population stays right where its at. If anything it may have gone down because apple warehouses have shutdown and moved to chelan and wenatchee | K31: Survey had ~1,100 / ~1,100 — correct as rounded; OFM 1,110 / 1,090 | L31: 1110 | M31: 1085 | N31: =((M31 - L31) / L31) * 100 -> -2.2522523 | O31: {=IF(M31 > MEDIAN(_xlfn._xlws.FILTER(M:M, C:C="Y")),"Y","N")} -> N | P31: =IF(N31 >= 10.15, "Y", "N") -> N | Q31: {=IF(N31 > MEDIAN(_xlfn._xlws.FILTER(N:N, C:C="Y")), "Y", "N")} -> N | R31: N | S31: We do sell to people that are off grid, so they get a water permit and get some amount of water at a time. We don’t sell to any towns or organizations though. | T31: Y | U31: N | V31: N | W31: No. | X31: N | Y31: =IF(C31="N", "", IF(AND(C31="Y", OR(AA31="Y", AB31="Y", AC31="Y", AD31="Y")), "Y", "N")) -> N | Z31: N/A | AA31: N/A | AB31: N/A | AC31: N/A | AD31: N/A | AE31: Y | AF31: There is a hookup fee. Varies by pipe size. | AG31: N | AH31: N | AI31: Y | AJ31: N | AK31: N | AL31: N | AM31: N | AN31: N | AO31: Y | AP31: Standard fee for 3 quarter inch, then you pay the difference on if you want a bigger size. Called a Connection Fee. | AQ31: Y | AR31: N | AS31: N | AT31: N | AU31: Y | AV31: In the progress of putting something like that together. Probably will be used both for assets and for meters. Used to be hand read meters, now we use radio read which makes GIS necessary. | AW31: Y | AX31: Y | AY31: N | BC31: went well. | BD31: 4967321 | BE31: FY2024 actual total expenditures, all funds (operating + capital/debt service). Source: WA State Auditor FIT, schedule1AggregationsByGovt (sections 30+35), MCAG 0541. portal.sao.wa.gov/FIT. | BF31: 2774647 | BG31: =BF31 /M31 -> 2557.2783 | BH31: 3170033 | BI31: 2715727 | BJ31: FY2024 Schedule 09 via SAO FIT API (Snapshots/Schedule9s, MCAG 0541). Col E 'Outstanding Debt' = CALCULATED: total LT principal EXCLUDING pension/OPEB/compensated absences (excluded by debt-type code — reliable). Col F 'Official Total Liabilities' = DIRECT: grand total of the Schedule 09 as filed with SAO (all liabilities incl. pension/OPEB; no pattern matching). WATER/SEWER portion ~$2,715,727 [REGEX/KEYWORD — IMPRECISE: matched on debt-description text only (no fund tag in FIT); approximate]. | BK31: =BH31 / M31 -> 2921.6894 | BL31: ='log(debt) vs log(pop.) normaliz'!H31 -> 1.0060189
A32: Okanogan | B32: Pateros | C32: Y | E32: Jord, City Manager | F32: Y | G32: not required to comply to gma | H32: Partially Planning | I32: N | J32: 10 people have come, so no. We have around 600 people total. | K32: Survey had 590 / 600. OFM shows 525 (2015) → 610 (2025). 2015 figure differs due to a state-certified special census | L32: 665 | M32: 600 | N32: =((M32 - L32) / L32) * 100 -> -9.7744361 | O32: {=IF(M32 > MEDIAN(_xlfn._xlws.FILTER(M:M, C:C="Y")),"Y","N")} -> N | P32: =IF(N32 >= 10.15, "Y", "N") -> N | Q32: {=IF(N32 > MEDIAN(_xlfn._xlws.FILTER(N:N, C:C="Y")), "Y", "N")} -> N | R32: N | S32: no. | T32: N | U32: N | V32: Y | W32: one major expansion. Finished it in 2019 | X32: Y | Y32: =IF(C32="N", "", IF(AND(C32="Y", OR(AA32="Y", AB32="Y", AC32="Y", AD32="Y")), "Y", "N")) -> N | Z32: NR | AA32: NR | AB32: NR | AC32: NR | AD32: NR | AE32: Y | AF32: off the top of my head, It was a $7.2 million project, we borrowed 1 million. The rest was through legislative appropriations and grants. No levying of upfront devlopment fees. We are maxed out on developmnet, due to our geography (mountains on one side, water on the other). We only have about 40 acres left for potential development. | AG32: N | AH32: N | AI32: N | AJ32: N | AK32: N | AL32: N | AM32: Y | AN32: Y | AO32: N/A | AQ32: N/A | AR32: N/A | AS32: N/A | AT32: N/A | AU32: Y | AV32: Yes we use a GIS, we have an asset management program. We have GIS locations on them. We also use a radio read for meters. We have asset management in our Gis, but we don’t really use it for budgetting. We mainly use it as a historical tool to know what happened in the ground | AW32: Y | AX32: N | AY32: Y | BA32: [nothing more to add] | BC32: went well. | BD32: 2868407 | BE32: FY2024 actual total expenditures, all funds (operating + capital/debt service). Source: WA State Auditor FIT, schedule1AggregationsByGovt (sections 30+35), MCAG 0537. portal.sao.wa.gov/FIT. | BF32: 1740031 | BG32: =BF32 /M32 -> 2900.0517 | BH32: 1823648 | BI32: 1729798 | BJ32: FY2024 Schedule 09 via SAO FIT API (Snapshots/Schedule9s, MCAG 0537). Col E 'Outstanding Debt' = CALCULATED: total LT principal EXCLUDING pension/OPEB/compensated absences (excluded by debt-type code — reliable). Col F 'Official Total Liabilities' = DIRECT: grand total of the Schedule 09 as filed with SAO (all liabilities incl. pension/OPEB; no pattern matching). WATER/SEWER portion ~$1,729,798 [REGEX/KEYWORD — IMPRECISE: matched on debt-description text only (no fund tag in FIT); approximate]. | BK32: =BH32 / M32 -> 3039.4133 | BL32: ='log(debt) vs log(pop.) normaliz'!H32 -> 1.0826442
